<?xml version="1.0" ?>
<robot name="arm" xmlns:xacro="http://www.ros.org/wiki/xacro">

<xacro:include filename="$(find arm_description)/urdf/materials.xacro" />
<xacro:include filename="$(find arm_description)/urdf/arm.ros2control" />
<xacro:include filename="$(find arm_description)/urdf/arm.gazebo" />
<link name="base_link">
  <inertial>
    <origin xyz="8.335040099330152e-18 8.335040099330152e-18 0.01" rpy="0 0 0"/>
    <mass value="1.070710717020314"/>
    <inertia ixx="0.000617" iyy="0.000617" izz="0.001162" ixy="0.0" iyz="0.0" ixz="0.0"/>
  </inertial>
  <visual>
    <origin xyz="0 0 0" rpy="0 0 0"/>
    <geometry>
      <mesh filename="file://$(find arm_description)/meshes/base_link.stl" scale="0.001 0.001 0.001"/>
    </geometry>
    <material name="silver"/>
  </visual>
  <collision>
    <origin xyz="0 0 0" rpy="0 0 0"/>
    <geometry>
      <mesh filename="file://$(find arm_description)/meshes/base_link.stl" scale="0.001 0.001 0.001"/>
    </geometry>
  </collision>
</link>

<link name="link1_1">
  <inertial>
    <origin xyz="2.915245639833243e-15 0.0 0.01482157442513447" rpy="0 0 0"/>
    <mass value="0.3455432805216625"/>
    <inertia ixx="9.8e-05" iyy="5.2e-05" izz="9.8e-05" ixy="0.0" iyz="0.0" ixz="-0.0"/>
  </inertial>
  <visual>
    <origin xyz="-0.0 -0.0 -0.02" rpy="0 0 0"/>
    <geometry>
      <mesh filename="file://$(find arm_description)/meshes/link1_1.stl" scale="0.001 0.001 0.001"/>
    </geometry>
    <material name="silver"/>
  </visual>
  <collision>
    <origin xyz="-0.0 -0.0 -0.02" rpy="0 0 0"/>
    <geometry>
      <mesh filename="file://$(find arm_description)/meshes/link1_1.stl" scale="0.001 0.001 0.001"/>
    </geometry>
  </collision>
</link>

<link name="link2_1">
  <inertial>
    <origin xyz="4.2312387934342156e-16 0.025 0.11917863722158455" rpy="0 0 0"/>
    <mass value="2.868475968312997"/>
    <inertia ixx="0.011517" iyy="0.010778" izz="0.001169" ixy="0.0" iyz="0.0" ixz="-0.0"/>
  </inertial>
  <visual>
    <origin xyz="0.0 0.025 -0.043" rpy="0 0 0"/>
    <geometry>
      <mesh filename="file://$(find arm_description)/meshes/link2_1.stl" scale="0.001 0.001 0.001"/>
    </geometry>
    <material name="silver"/>
  </visual>
  <collision>
    <origin xyz="0.0 0.025 -0.043" rpy="0 0 0"/>
    <geometry>
      <mesh filename="file://$(find arm_description)/meshes/link2_1.stl" scale="0.001 0.001 0.001"/>
    </geometry>
  </collision>
</link>

<link name="link3_1">
  <inertial>
    <origin xyz="1.6071289105825086e-15 0.02 0.09952756543650632" rpy="0 0 0"/>
    <mass value="2.0129692488346587"/>
    <inertia ixx="0.007958" iyy="0.007842" izz="0.00042" ixy="0.0" iyz="0.0" ixz="0.0"/>
  </inertial>
  <visual>
    <origin xyz="0.0 0.02 -0.273" rpy="0 0 0"/>
    <geometry>
      <mesh filename="file://$(find arm_description)/meshes/link3_1.stl" scale="0.001 0.001 0.001"/>
    </geometry>
    <material name="silver"/>
  </visual>
  <collision>
    <origin xyz="0.0 0.02 -0.273" rpy="0 0 0"/>
    <geometry>
      <mesh filename="file://$(find arm_description)/meshes/link3_1.stl" scale="0.001 0.001 0.001"/>
    </geometry>
  </collision>
</link>

<link name="link4_1">
  <inertial>
    <origin xyz="-8.145876330549066e-16 0.019999999999999997 0.0489382381034012" rpy="0 0 0"/>
    <mass value="0.986017312208665"/>
    <inertia ixx="0.001006" iyy="0.000715" izz="0.00044" ixy="0.0" iyz="0.0" ixz="-0.0"/>
  </inertial>
  <visual>
    <origin xyz="0.0 0.02 -0.463" rpy="0 0 0"/>
    <geometry>
      <mesh filename="file://$(find arm_description)/meshes/link4_1.stl" scale="0.001 0.001 0.001"/>
    </geometry>
    <material name="silver"/>
  </visual>
  <collision>
    <origin xyz="0.0 0.02 -0.463" rpy="0 0 0"/>
    <geometry>
      <mesh filename="file://$(find arm_description)/meshes/link4_1.stl" scale="0.001 0.001 0.001"/>
    </geometry>
  </collision>
</link>

<joint name="j1" type="continuous">
  <origin xyz="0.0 0.0 0.02" rpy="0 0 0"/>
  <parent link="base_link"/>
  <child link="link1_1"/>
  <axis xyz="0.0 0.0 1.0"/>
</joint>

<joint name="j2" type="continuous">
  <origin xyz="-0.0 -0.025 0.023" rpy="0 0 0"/>
  <parent link="link1_1"/>
  <child link="link2_1"/>
  <axis xyz="0.0 1.0 0.0"/>
</joint>

<joint name="j3" type="continuous">
  <origin xyz="0.0 0.005 0.23" rpy="0 0 0"/>
  <parent link="link2_1"/>
  <child link="link3_1"/>
  <axis xyz="0.0 1.0 0.0"/>
</joint>

<joint name="j4" type="continuous">
  <origin xyz="0.0 0.0 0.19" rpy="0 0 0"/>
  <parent link="link3_1"/>
  <child link="link4_1"/>
  <axis xyz="0.0 1.0 0.0"/>
</joint>

</robot>
